<?xml version="1.0" encoding="UTF-8"?>
<!-- Generated by org.testng.reporters.JUnitReportReporter -->
<testsuite hostname="DESKTOP-GN1IAVO" name="com.noc.testing.FillNocForm" tests="2" failures="1" timestamp="12 Mar 2020 21:04:00 GMT" time="9.353" errors="0">
  <testcase name="fillFormWithValidData" time="6.977" classname="com.noc.testing.FillNocForm"/>
  <testcase name="fillFormWithInvalidData" time="2.376" classname="com.noc.testing.FillNocForm">
    <failure type="java.lang.AssertionError" message="expected [Thank You] but found [Daily ABB (PCD2) &amp; Dustex(PCD3) Inspection]">
      <![CDATA[java.lang.AssertionError: expected [Thank You] but found [Daily ABB (PCD2) & Dustex(PCD3) Inspection]
	at org.testng.Assert.fail(Assert.java:94)
	at org.testng.Assert.failNotEquals(Assert.java:513)
	at org.testng.Assert.assertEqualsImpl(Assert.java:135)
	at org.testng.Assert.assertEquals(Assert.java:116)
	at org.testng.Assert.assertEquals(Assert.java:190)
	at org.testng.Assert.assertEquals(Assert.java:200)
	at com.noc.testing.FillNocForm.fillFormWithInvalidData(FillNocForm.java:81)
	at sun.reflect.NativeMethodAccessorImpl.invoke0(Native Method)
	at sun.reflect.NativeMethodAccessorImpl.invoke(NativeMethodAccessorImpl.java:62)
	at sun.reflect.DelegatingMethodAccessorImpl.invoke(DelegatingMethodAccessorImpl.java:43)
	at java.lang.reflect.Method.invoke(Method.java:498)
	at org.testng.internal.MethodInvocationHelper.invokeMethod(MethodInvocationHelper.java:86)
	at org.testng.internal.Invoker.invokeMethod(Invoker.java:645)
	at org.testng.internal.Invoker.invokeTestMethod(Invoker.java:822)
	at org.testng.internal.Invoker.invokeTestMethods(Invoker.java:1130)
	at org.testng.internal.TestMethodWorker.invokeTestMethods(TestMethodWorker.java:129)
	at org.testng.internal.TestMethodWorker.run(TestMethodWorker.java:112)
	at org.testng.TestRunner.privateRun(TestRunner.java:782)
	at org.testng.TestRunner.run(TestRunner.java:632)
	at org.testng.SuiteRunner.runTest(SuiteRunner.java:366)
	at org.testng.SuiteRunner.runSequentially(SuiteRunner.java:361)
	at org.testng.SuiteRunner.privateRun(SuiteRunner.java:319)
	at org.testng.SuiteRunner.run(SuiteRunner.java:268)
	at org.testng.SuiteRunnerWorker.runSuite(SuiteRunnerWorker.java:52)
	at org.testng.SuiteRunnerWorker.run(SuiteRunnerWorker.java:86)
	at org.testng.TestNG.runSuitesSequentially(TestNG.java:1244)
	at org.testng.TestNG.runSuitesLocally(TestNG.java:1169)
	at org.testng.TestNG.run(TestNG.java:1064)
	at org.testng.remote.RemoteTestNG.run(RemoteTestNG.java:113)
	at org.testng.remote.RemoteTestNG.initAndRun(RemoteTestNG.java:206)
	at org.testng.remote.RemoteTestNG.main(RemoteTestNG.java:177)
]]>
    </failure>
  </testcase> <!-- fillFormWithInvalidData -->
</testsuite> <!-- com.noc.testing.FillNocForm -->
